{
  "version": 8,
  "blockIdVersion": 11,
  "anchorX": 0,
  "anchorY": 0,
  "anchorZ": 0,
  "blocks": [
    {
      "x": -3,
      "y": 11,
      "z": -2,
      "name": "Rock_Calcite_Brick_Smooth_Half",
      "rotation": 7
    },
    {
      "x": -3,
      "y": 12,
      "z": -2,
      "name": "Rock_Calcite_Brick_Smooth_Half",
      "rotation": 7
    },
    {
      "x": -3,
      "y": 13,
      "z": -2,
      "name": "Rock_Calcite_Brick_Smooth_Half",
      "rotation": 7
    },
    {
      "x": -3,
      "y": 14,
      "z": -2,
      "name": "Rock_Calcite_Brick_Smooth_Half",
      "rotation": 7
    },
    {
      "x": -3,
      "y": 11,
      "z": -1,
      "name": "Rock_Calcite_Brick_Smooth_Half",
      "rotation": 7
    },
    {
      "x": -3,
      "y": 12,
      "z": -1,
      "name": "Rock_Calcite_Brick_Smooth_Half",
      "rotation": 7
    },
    {
      "x": -3,
      "y": 13,
      "z": -1,
      "name": "Rock_Calcite_Brick_Smooth_Half",
      "rotation": 7
    },
    {
      "x": -3,
      "y": 14,
      "z": -1,
      "name": "Rock_Calcite_Brick_Smooth_Half",
      "rotation": 7
    },
    {
      "x": -3,
      "y": 11,
      "z": 0,
      "name": "Rock_Calcite_Brick_Smooth_Half",
      "rotation": 7
    },
    {
      "x": -3,
      "y": 12,
      "z": 0,
      "name": "Rock_Calcite_Brick_Smooth_Half",
      "rotation": 7
    },
    {
      "x": -3,
      "y": 13,
      "z": 0,
      "name": "Rock_Calcite_Brick_Smooth_Half",
      "rotation": 7
    },
    {
      "x": -3,
      "y": 14,
      "z": 0,
      "name": "Rock_Calcite_Brick_Smooth_Half",
      "rotation": 7
    },
    {
      "x": -3,
      "y": 11,
      "z": 1,
      "name": "Rock_Calcite_Brick_Smooth_Half",
      "rotation": 7
    },
    {
      "x": -3,
      "y": 12,
      "z": 1,
      "name": "Rock_Calcite_Brick_Smooth_Half",
      "rotation": 7
    },
    {
      "x": -3,
      "y": 13,
      "z": 1,
      "name": "Rock_Calcite_Brick_Smooth_Half",
      "rotation": 7
    },
    {
      "x": -3,
      "y": 14,
      "z": 1,
      "name": "Rock_Calcite_Brick_Smooth_Half",
      "rotation": 7
    },
    {
      "x": -3,
      "y": 11,
      "z": 2,
      "name": "Rock_Calcite_Brick_Smooth_Half",
      "rotation": 7
    },
    {
      "x": -3,
      "y": 12,
      "z": 2,
      "name": "Rock_Calcite_Brick_Smooth_Half",
      "rotation": 7
    },
    {
      "x": -3,
      "y": 13,
      "z": 2,
      "name": "Rock_Calcite_Brick_Smooth_Half",
      "rotation": 7
    },
    {
      "x": -3,
      "y": 14,
      "z": 2,
      "name": "Rock_Calcite_Brick_Smooth_Half",
      "rotation": 7
    },
    {
      "x": -2,
      "y": 11,
      "z": -3,
      "name": "Rock_Calcite_Brick_Smooth_Half",
      "rotation": 6
    },
    {
      "x": -2,
      "y": 12,
      "z": -3,
      "name": "Rock_Calcite_Brick_Smooth_Half",
      "rotation": 6
    },
    {
      "x": -2,
      "y": 13,
      "z": -3,
      "name": "Rock_Calcite_Brick_Smooth_Half",
      "rotation": 6
    },
    {
      "x": -2,
      "y": 14,
      "z": -3,
      "name": "Rock_Calcite_Brick_Smooth_Half",
      "rotation": 6
    },
    {
      "x": -2,
      "y": 10,
      "z": -2,
      "name": "*Rock_Calcite_Brick_Stairs_State_Definitions_Corner_Left",
      "rotation": 9
    },
    {
      "x": -2,
      "y": 10,
      "z": -1,
      "name": "Rock_Calcite_Brick_Stairs",
      "rotation": 9
    },
    {
      "x": -2,
      "y": 10,
      "z": 0,
      "name": "Rock_Calcite_Brick_Stairs",
      "rotation": 9
    },
    {
      "x": -2,
      "y": 10,
      "z": 1,
      "name": "Rock_Calcite_Brick_Stairs",
      "rotation": 9
    },
    {
      "x": -2,
      "y": 10,
      "z": 2,
      "name": "*Rock_Calcite_Brick_Stairs_State_Definitions_Corner_Left",
      "rotation": 10
    },
    {
      "x": -2,
      "y": 11,
      "z": 3,
      "name": "Rock_Calcite_Brick_Smooth_Half",
      "rotation": 4
    },
    {
      "x": -2,
      "y": 12,
      "z": 3,
      "name": "Rock_Calcite_Brick_Smooth_Half",
      "rotation": 4
    },
    {
      "x": -2,
      "y": 13,
      "z": 3,
      "name": "Rock_Calcite_Brick_Smooth_Half",
      "rotation": 4
    },
    {
      "x": -2,
      "y": 14,
      "z": 3,
      "name": "Rock_Calcite_Brick_Smooth_Half",
      "rotation": 4
    },
    {
      "x": -1,
      "y": 11,
      "z": -3,
      "name": "Rock_Calcite_Brick_Smooth_Half",
      "rotation": 6
    },
    {
      "x": -1,
      "y": 12,
      "z": -3,
      "name": "Rock_Calcite_Brick_Smooth_Half",
      "rotation": 6
    },
    {
      "x": -1,
      "y": 13,
      "z": -3,
      "name": "Rock_Calcite_Brick_Smooth_Half",
      "rotation": 6
    },
    {
      "x": -1,
      "y": 14,
      "z": -3,
      "name": "Rock_Calcite_Brick_Smooth_Half",
      "rotation": 6
    },
    {
      "x": -1,
      "y": 10,
      "z": -2,
      "name": "Rock_Calcite_Brick_Stairs",
      "rotation": 8
    },
    {
      "x": -1,
      "y": 9,
      "z": -1,
      "name": "*Rock_Calcite_Brick_Stairs_State_Definitions_Corner_Right",
      "rotation": 8
    },
    {
      "x": -1,
      "y": 10,
      "z": -1,
      "name": "Rock_Crystal_Wind_Block"
    },
    {
      "x": -1,
      "y": 11,
      "z": -1,
      "name": "Rock_Crystal_Wind_Block"
    },
    {
      "x": -1,
      "y": 9,
      "z": 0,
      "name": "Rock_Calcite_Brick_Stairs",
      "rotation": 9
    },
    {
      "x": -1,
      "y": 10,
      "z": 0,
      "name": "Rock_Crystal_Wind_Block"
    },
    {
      "x": -1,
      "y": 11,
      "z": 0,
      "name": "Rock_Crystal_Wind_Block"
    },
    {
      "x": -1,
      "y": 9,
      "z": 1,
      "name": "*Rock_Calcite_Brick_Stairs_State_Definitions_Corner_Left",
      "rotation": 10
    },
    {
      "x": -1,
      "y": 10,
      "z": 1,
      "name": "Rock_Crystal_Wind_Block",
      "rotation": 5
    },
    {
      "x": -1,
      "y": 11,
      "z": 1,
      "name": "Rock_Crystal_Wind_Block"
    },
    {
      "x": -1,
      "y": 10,
      "z": 2,
      "name": "Rock_Calcite_Brick_Stairs",
      "rotation": 10
    },
    {
      "x": -1,
      "y": 11,
      "z": 3,
      "name": "Rock_Calcite_Brick_Smooth_Half",
      "rotation": 4
    },
    {
      "x": -1,
      "y": 12,
      "z": 3,
      "name": "Rock_Calcite_Brick_Smooth_Half",
      "rotation": 4
    },
    {
      "x": -1,
      "y": 13,
      "z": 3,
      "name": "Rock_Calcite_Brick_Smooth_Half",
      "rotation": 4
    },
    {
      "x": -1,
      "y": 14,
      "z": 3,
      "name": "Rock_Calcite_Brick_Smooth_Half",
      "rotation": 4
    },
    {
      "x": 0,
      "y": 11,
      "z": -3,
      "name": "Rock_Calcite_Brick_Smooth_Half",
      "rotation": 6
    },
    {
      "x": 0,
      "y": 12,
      "z": -3,
      "name": "Rock_Calcite_Brick_Smooth_Half",
      "rotation": 6
    },
    {
      "x": 0,
      "y": 13,
      "z": -3,
      "name": "Rock_Calcite_Brick_Smooth_Half",
      "rotation": 6
    },
    {
      "x": 0,
      "y": 14,
      "z": -3,
      "name": "Rock_Calcite_Brick_Smooth_Half",
      "rotation": 6
    },
    {
      "x": 0,
      "y": 10,
      "z": -2,
      "name": "Rock_Calcite_Brick_Stairs",
      "rotation": 8
    },
    {
      "x": 0,
      "y": 9,
      "z": -1,
      "name": "Rock_Calcite_Brick_Stairs",
      "rotation": 8
    },
    {
      "x": 0,
      "y": 10,
      "z": -1,
      "name": "Rock_Crystal_Wind_Block"
    },
    {
      "x": 0,
      "y": 11,
      "z": -1,
      "name": "Rock_Crystal_Wind_Block"
    },
    {
      "x": 0,
      "y": -5,
      "z": 0,
      "name": "Rock_Calcite_Brick_Smooth"
    },
    {
      "x": 0,
      "y": -4,
      "z": 0,
      "name": "Rock_Calcite_Brick_Smooth"
    },
    {
      "x": 0,
      "y": -3,
      "z": 0,
      "name": "Rock_Calcite_Brick_Smooth"
    },
    {
      "x": 0,
      "y": -2,
      "z": 0,
      "name": "Rock_Calcite_Brick_Smooth"
    },
    {
      "x": 0,
      "y": -1,
      "z": 0,
      "name": "Rock_Calcite_Brick_Smooth"
    },
    {
      "x": 0,
      "y": 0,
      "z": 0,
      "name": "Rock_Calcite_Brick_Pillar_Base"
    },
    {
      "x": 0,
      "y": 1,
      "z": 0,
      "name": "Rock_Calcite_Brick_Pillar_Base"
    },
    {
      "x": 0,
      "y": 2,
      "z": 0,
      "name": "Rock_Calcite_Brick_Pillar_Middle"
    },
    {
      "x": 0,
      "y": 3,
      "z": 0,
      "name": "Rock_Calcite_Brick_Pillar_Middle"
    },
    {
      "x": 0,
      "y": 4,
      "z": 0,
      "name": "Rock_Calcite_Brick_Pillar_Middle"
    },
    {
      "x": 0,
      "y": 5,
      "z": 0,
      "name": "Rock_Calcite_Brick_Pillar_Middle"
    },
    {
      "x": 0,
      "y": 6,
      "z": 0,
      "name": "Rock_Calcite_Brick_Pillar_Middle"
    },
    {
      "x": 0,
      "y": 7,
      "z": 0,
      "name": "Rock_Calcite_Brick_Pillar_Middle"
    },
    {
      "x": 0,
      "y": 8,
      "z": 0,
      "name": "Rock_Calcite_Brick_Pillar_Base",
      "rotation": 8
    },
    {
      "x": 0,
      "y": 9,
      "z": 0,
      "name": "Rock_Crystal_Wind_Block"
    },
    {
      "x": 0,
      "y": 10,
      "z": 0,
      "name": "Rock_Crystal_Wind_Block"
    },
    {
      "x": 0,
      "y": 11,
      "z": 0,
      "name": "Rock_Crystal_Wind_Block"
    },
    {
      "x": 0,
      "y": 12,
      "z": 0,
      "name": "Spawner_Wind_Sprite",
      "components": {
        "Components": {
          "PlacedByInteraction": {
            "WhoPlacedUuid": {
              "$binary": "bqDSATiwT++EkU6x0gHadg==",
              "$type": "04"
            }
          },
          "SpawnMarkerBlock": {
            "MarkerReference": {
              "UUID": {
                "$binary": "A6avU+scM9qxoVfvC6zE1Q==",
                "$type": "04"
              }
            }
          }
        }
      }
    },
    {
      "x": 0,
      "y": 9,
      "z": 1,
      "name": "Rock_Calcite_Brick_Stairs",
      "rotation": 10
    },
    {
      "x": 0,
      "y": 10,
      "z": 1,
      "name": "Rock_Crystal_Wind_Block"
    },
    {
      "x": 0,
      "y": 11,
      "z": 1,
      "name": "Rock_Crystal_Wind_Block"
    },
    {
      "x": 0,
      "y": 10,
      "z": 2,
      "name": "Rock_Calcite_Brick_Stairs",
      "rotation": 10
    },
    {
      "x": 0,
      "y": 11,
      "z": 3,
      "name": "Rock_Calcite_Brick_Smooth_Half",
      "rotation": 4
    },
    {
      "x": 0,
      "y": 12,
      "z": 3,
      "name": "Rock_Calcite_Brick_Smooth_Half",
      "rotation": 4
    },
    {
      "x": 0,
      "y": 13,
      "z": 3,
      "name": "Rock_Calcite_Brick_Smooth_Half",
      "rotation": 4
    },
    {
      "x": 0,
      "y": 14,
      "z": 3,
      "name": "Rock_Calcite_Brick_Smooth_Half",
      "rotation": 4
    },
    {
      "x": 1,
      "y": 11,
      "z": -3,
      "name": "Rock_Calcite_Brick_Smooth_Half",
      "rotation": 6
    },
    {
      "x": 1,
      "y": 12,
      "z": -3,
      "name": "Rock_Calcite_Brick_Smooth_Half",
      "rotation": 6
    },
    {
      "x": 1,
      "y": 13,
      "z": -3,
      "name": "Rock_Calcite_Brick_Smooth_Half",
      "rotation": 6
    },
    {
      "x": 1,
      "y": 14,
      "z": -3,
      "name": "Rock_Calcite_Brick_Smooth_Half",
      "rotation": 6
    },
    {
      "x": 1,
      "y": 10,
      "z": -2,
      "name": "Rock_Calcite_Brick_Stairs",
      "rotation": 8
    },
    {
      "x": 1,
      "y": 9,
      "z": -1,
      "name": "*Rock_Calcite_Brick_Stairs_State_Definitions_Corner_Right",
      "rotation": 11
    },
    {
      "x": 1,
      "y": 10,
      "z": -1,
      "name": "Rock_Crystal_Wind_Block"
    },
    {
      "x": 1,
      "y": 11,
      "z": -1,
      "name": "Rock_Crystal_Wind_Block"
    },
    {
      "x": 1,
      "y": 9,
      "z": 0,
      "name": "Rock_Calcite_Brick_Stairs",
      "rotation": 11
    },
    {
      "x": 1,
      "y": 10,
      "z": 0,
      "name": "Rock_Crystal_Wind_Block"
    },
    {
      "x": 1,
      "y": 11,
      "z": 0,
      "name": "Rock_Crystal_Wind_Block"
    },
    {
      "x": 1,
      "y": 9,
      "z": 1,
      "name": "*Rock_Calcite_Brick_Stairs_State_Definitions_Corner_Left",
      "rotation": 11
    },
    {
      "x": 1,
      "y": 10,
      "z": 1,
      "name": "Rock_Crystal_Wind_Block"
    },
    {
      "x": 1,
      "y": 11,
      "z": 1,
      "name": "Rock_Crystal_Wind_Block"
    },
    {
      "x": 1,
      "y": 10,
      "z": 2,
      "name": "Rock_Calcite_Brick_Stairs",
      "rotation": 10
    },
    {
      "x": 1,
      "y": 11,
      "z": 3,
      "name": "Rock_Calcite_Brick_Smooth_Half",
      "rotation": 4
    },
    {
      "x": 1,
      "y": 12,
      "z": 3,
      "name": "Rock_Calcite_Brick_Smooth_Half",
      "rotation": 4
    },
    {
      "x": 1,
      "y": 13,
      "z": 3,
      "name": "Rock_Calcite_Brick_Smooth_Half",
      "rotation": 4
    },
    {
      "x": 1,
      "y": 14,
      "z": 3,
      "name": "Rock_Calcite_Brick_Smooth_Half",
      "rotation": 4
    },
    {
      "x": 2,
      "y": 11,
      "z": -3,
      "name": "Rock_Calcite_Brick_Smooth_Half",
      "rotation": 6
    },
    {
      "x": 2,
      "y": 12,
      "z": -3,
      "name": "Rock_Calcite_Brick_Smooth_Half",
      "rotation": 6
    },
    {
      "x": 2,
      "y": 13,
      "z": -3,
      "name": "Rock_Calcite_Brick_Smooth_Half",
      "rotation": 6
    },
    {
      "x": 2,
      "y": 14,
      "z": -3,
      "name": "Rock_Calcite_Brick_Smooth_Half",
      "rotation": 6
    },
    {
      "x": 2,
      "y": 10,
      "z": -2,
      "name": "*Rock_Calcite_Brick_Stairs_State_Definitions_Corner_Left",
      "rotation": 8
    },
    {
      "x": 2,
      "y": 10,
      "z": -1,
      "name": "Rock_Calcite_Brick_Stairs",
      "rotation": 11
    },
    {
      "x": 2,
      "y": 10,
      "z": 0,
      "name": "Rock_Calcite_Brick_Stairs",
      "rotation": 11
    },
    {
      "x": 2,
      "y": 10,
      "z": 1,
      "name": "Rock_Calcite_Brick_Stairs",
      "rotation": 11
    },
    {
      "x": 2,
      "y": 10,
      "z": 2,
      "name": "*Rock_Calcite_Brick_Stairs_State_Definitions_Corner_Right",
      "rotation": 10
    },
    {
      "x": 2,
      "y": 11,
      "z": 3,
      "name": "Rock_Calcite_Brick_Smooth_Half",
      "rotation": 4
    },
    {
      "x": 2,
      "y": 12,
      "z": 3,
      "name": "Rock_Calcite_Brick_Smooth_Half",
      "rotation": 4
    },
    {
      "x": 2,
      "y": 13,
      "z": 3,
      "name": "Rock_Calcite_Brick_Smooth_Half",
      "rotation": 4
    },
    {
      "x": 2,
      "y": 14,
      "z": 3,
      "name": "Rock_Calcite_Brick_Smooth_Half",
      "rotation": 4
    },
    {
      "x": 3,
      "y": 11,
      "z": -2,
      "name": "Rock_Calcite_Brick_Smooth_Half",
      "rotation": 5
    },
    {
      "x": 3,
      "y": 12,
      "z": -2,
      "name": "Rock_Calcite_Brick_Smooth_Half",
      "rotation": 5
    },
    {
      "x": 3,
      "y": 13,
      "z": -2,
      "name": "Rock_Calcite_Brick_Smooth_Half",
      "rotation": 5
    },
    {
      "x": 3,
      "y": 14,
      "z": -2,
      "name": "Rock_Calcite_Brick_Smooth_Half",
      "rotation": 5
    },
    {
      "x": 3,
      "y": 11,
      "z": -1,
      "name": "Rock_Calcite_Brick_Smooth_Half",
      "rotation": 5
    },
    {
      "x": 3,
      "y": 12,
      "z": -1,
      "name": "Rock_Calcite_Brick_Smooth_Half",
      "rotation": 5
    },
    {
      "x": 3,
      "y": 13,
      "z": -1,
      "name": "Rock_Calcite_Brick_Smooth_Half",
      "rotation": 5
    },
    {
      "x": 3,
      "y": 14,
      "z": -1,
      "name": "Rock_Calcite_Brick_Smooth_Half",
      "rotation": 5
    },
    {
      "x": 3,
      "y": 11,
      "z": 0,
      "name": "Rock_Calcite_Brick_Smooth_Half",
      "rotation": 5
    },
    {
      "x": 3,
      "y": 12,
      "z": 0,
      "name": "Rock_Calcite_Brick_Smooth_Half",
      "rotation": 5
    },
    {
      "x": 3,
      "y": 13,
      "z": 0,
      "name": "Rock_Calcite_Brick_Smooth_Half",
      "rotation": 5
    },
    {
      "x": 3,
      "y": 14,
      "z": 0,
      "name": "Rock_Calcite_Brick_Smooth_Half",
      "rotation": 5
    },
    {
      "x": 3,
      "y": 11,
      "z": 1,
      "name": "Rock_Calcite_Brick_Smooth_Half",
      "rotation": 5
    },
    {
      "x": 3,
      "y": 12,
      "z": 1,
      "name": "Rock_Calcite_Brick_Smooth_Half",
      "rotation": 5
    },
    {
      "x": 3,
      "y": 13,
      "z": 1,
      "name": "Rock_Calcite_Brick_Smooth_Half",
      "rotation": 5
    },
    {
      "x": 3,
      "y": 14,
      "z": 1,
      "name": "Rock_Calcite_Brick_Smooth_Half",
      "rotation": 5
    },
    {
      "x": 3,
      "y": 11,
      "z": 2,
      "name": "Rock_Calcite_Brick_Smooth_Half",
      "rotation": 5
    },
    {
      "x": 3,
      "y": 12,
      "z": 2,
      "name": "Rock_Calcite_Brick_Smooth_Half",
      "rotation": 5
    },
    {
      "x": 3,
      "y": 13,
      "z": 2,
      "name": "Rock_Calcite_Brick_Smooth_Half",
      "rotation": 5
    },
    {
      "x": 3,
      "y": 14,
      "z": 2,
      "name": "Rock_Calcite_Brick_Smooth_Half",
      "rotation": 5
    }
  ],
  "entities": [
    {
      "Components": {
        "UtilityInventory": {
          "Inventory": {
            "Id": "Empty"
          },
          "ActiveSlot": -1
        },
        "EffectController": {},
        "DisplayName": {
          "DisplayName": {
            "MessageId": "server.npcRoles.Template.name",
            "Bold": null,
            "Italic": null,
            "Monospace": null,
            "Underline": null
          }
        },
        "RefId": {
          "Count": 0
        },
        "UIComponentList": {},
        "HotbarInventory": {
          "Inventory": {
            "Id": "Simple",
            "Capacity": 3,
            "Items": {}
          },
          "ActiveSlot": 0
        },
        "Transform": {
          "Position": {
            "X": -0.061300430043374377,
            "Y": 12.0,
            "Z": 1.7094232537692307
          },
          "Rotation": {
            "Pitch": 0.0,
            "Yaw": 1.9105679988861084,
            "Roll": 0.0
          }
        },
        "StorageInventory": {
          "Inventory": {
            "Id": "Empty"
          }
        },
        "Velocity": {
          "Velocity": {
            "X": 0.0,
            "Y": 0.0,
            "Z": 0.0
          }
        },
        "PrefabCopyable": {},
        "Interactions": {
          "Interactions": {
            "Use": "*UseNPC"
          }
        },
        "Model": {
          "Model": {
            "Id": "Wind_Sprite",
            "Scale": 1.0170941352844238,
            "Static": false
          }
        },
        "UUID": {
          "UUID": {
            "$binary": "P4lfQU9ENyOoIt104ohIxQ==",
            "$type": "04"
          }
        },
        "EntityStats": {
          "Version": 5,
          "Stats": {
            "Oxygen": {
              "Id": "Oxygen",
              "Value": 100.0
            },
            "Mana": {
              "Id": "Mana",
              "Value": 0.0
            },
            "Shield": {
              "Id": "Shield",
              "Value": 10.0
            },
            "Health": {
              "Id": "Health",
              "Value": 70.0,
              "Modifiers": {
                "NPC_Max": {
                  "Id": "Static",
                  "CalculationType": "Additive",
                  "Amount": -30.0
                }
              }
            },
            "GlidingActive": {
              "Id": "GlidingActive",
              "Value": 0.0
            },
            "Immunity": {
              "Id": "Immunity",
              "Value": 0.0
            },
            "ShieldActive": {
              "Id": "ShieldActive",
              "Value": 0.0
            },
            "SignatureCharges": {
              "Id": "SignatureCharges",
              "Value": 0.0
            },
            "Stamina": {
              "Id": "Stamina",
              "Value": 10.0
            },
            "Ammo": {
              "Id": "Ammo",
              "Value": 0.0
            },
            "Unknown": {
              "Id": "Unknown",
              "Value": 0.0
            },
            "SignatureEnergy": {
              "Id": "SignatureEnergy",
              "Value": 0.0
            },
            "DeployablePreview": {
              "Id": "DeployablePreview",
              "Value": 0.0
            },
            "StaminaRegenDelay": {
              "Id": "StaminaRegenDelay",
              "Value": 0.0
            },
            "MagicCharges": {
              "Id": "MagicCharges",
              "Value": 0.0
            }
          }
        },
        "SpawnMarkerReference": {
          "SpawnMarker": {
            "UUID": {
              "$binary": "A6avU+scM9qxoVfvC6zE1Q==",
              "$type": "04"
            },
            "RefCount": 0
          }
        },
        "WorldGenId": {
          "WorldGenId": 0
        },
        "NPC": {
          "Version": 5,
          "UUID": {
            "$binary": "P4lfQU9ENyOoIt104ohIxQ==",
            "$type": "04"
          },
          "Inventory": {
            "Version": 4,
            "ActiveHotbarSlot": 0,
            "ActiveToolsSlot": -1,
            "ActiveUtilitySlot": -1
          },
          "HvrPhs": 0.0,
          "HvrHght": 0.0,
          "MdlScl": 1.0170941352844238,
          "SpawnInstant": "0001-01-03T12:00:00Z",
          "WorldgenId": 0,
          "PathManager": {},
          "LeashPos": {
            "X": -5.5,
            "Y": 98.0,
            "Z": 81.5
          },
          "LeashHdg": 0.0,
          "LeashPtch": 0.0,
          "RoleName": "Wind_Sprite"
        },
        "ArmorInventory": {
          "Inventory": {
            "Id": "Simple",
            "Capacity": 4,
            "Items": {}
          }
        },
        "HeadRotation": {
          "Rotation": {
            "Pitch": 0.0,
            "Yaw": 1.9105679988861084,
            "Roll": 0.0
          }
        }
      }
    },
    {
      "Components": {
        "UtilityInventory": {
          "Inventory": {
            "Id": "Empty"
          },
          "ActiveSlot": -1
        },
        "EffectController": {},
        "DisplayName": {
          "DisplayName": {
            "MessageId": "server.npcRoles.Template.name",
            "Bold": null,
            "Italic": null,
            "Monospace": null,
            "Underline": null
          }
        },
        "UIComponentList": {},
        "HotbarInventory": {
          "Inventory": {
            "Id": "Simple",
            "Capacity": 3,
            "Items": {}
          },
          "ActiveSlot": 0
        },
        "Transform": {
          "Position": {
            "X": 0.5333711346935495,
            "Y": 13.0,
            "Z": 0.3114635539516968
          },
          "Rotation": {
            "Pitch": 0.0,
            "Yaw": -1.763379693031311,
            "Roll": 0.0
          }
        },
        "StorageInventory": {
          "Inventory": {
            "Id": "Empty"
          }
        },
        "Velocity": {
          "Velocity": {
            "X": 0.0,
            "Y": 0.0,
            "Z": 0.0
          }
        },
        "PrefabCopyable": {},
        "Interactions": {
          "Interactions": {
            "Use": "*UseNPC"
          }
        },
        "Model": {
          "Model": {
            "Id": "Wind_Sprite",
            "Scale": 0.9602376222610474,
            "Static": false
          }
        },
        "UUID": {
          "UUID": {
            "$binary": "Yzs/PsbJPPSZ9Yx5S2IeOw==",
            "$type": "04"
          }
        },
        "EntityStats": {
          "Version": 5,
          "Stats": {
            "Oxygen": {
              "Id": "Oxygen",
              "Value": 100.0
            },
            "Mana": {
              "Id": "Mana",
              "Value": 0.0
            },
            "Shield": {
              "Id": "Shield",
              "Value": 10.0
            },
            "Health": {
              "Id": "Health",
              "Value": 70.0,
              "Modifiers": {
                "NPC_Max": {
                  "Id": "Static",
                  "CalculationType": "Additive",
                  "Amount": -30.0
                }
              }
            },
            "GlidingActive": {
              "Id": "GlidingActive",
              "Value": 0.0
            },
            "Immunity": {
              "Id": "Immunity",
              "Value": 0.0
            },
            "ShieldActive": {
              "Id": "ShieldActive",
              "Value": 0.0
            },
            "SignatureCharges": {
              "Id": "SignatureCharges",
              "Value": 0.0
            },
            "Stamina": {
              "Id": "Stamina",
              "Value": 10.0
            },
            "Ammo": {
              "Id": "Ammo",
              "Value": 0.0
            },
            "Unknown": {
              "Id": "Unknown",
              "Value": 0.0
            },
            "SignatureEnergy": {
              "Id": "SignatureEnergy",
              "Value": 0.0
            },
            "DeployablePreview": {
              "Id": "DeployablePreview",
              "Value": 0.0
            },
            "StaminaRegenDelay": {
              "Id": "StaminaRegenDelay",
              "Value": 0.0
            },
            "MagicCharges": {
              "Id": "MagicCharges",
              "Value": 0.0
            }
          }
        },
        "NPC": {
          "Version": 5,
          "UUID": {
            "$binary": "Yzs/PsbJPPSZ9Yx5S2IeOw==",
            "$type": "04"
          },
          "Inventory": {
            "Version": 4,
            "ActiveHotbarSlot": 0,
            "ActiveToolsSlot": -1,
            "ActiveUtilitySlot": -1
          },
          "HvrPhs": 0.0,
          "HvrHght": 0.0,
          "MdlScl": 0.9602376222610474,
          "SpawnInstant": "0001-01-03T12:00:00Z",
          "WorldgenId": 0,
          "PathManager": {},
          "LeashPos": {
            "X": -4.490226421944354,
            "Y": 97.0,
            "Z": 81.24926418656928
          },
          "LeashHdg": 3.096343755722046,
          "LeashPtch": 0.0,
          "RoleName": "Wind_Sprite"
        },
        "ArmorInventory": {
          "Inventory": {
            "Id": "Simple",
            "Capacity": 4,
            "Items": {}
          }
        },
        "HeadRotation": {
          "Rotation": {
            "Pitch": 0.0,
            "Yaw": -1.7633795738220215,
            "Roll": 0.0
          }
        }
      }
    },
    {
      "Components": {
        "UtilityInventory": {
          "Inventory": {
            "Id": "Empty"
          },
          "ActiveSlot": -1
        },
        "EffectController": {},
        "DisplayName": {
          "DisplayName": {
            "MessageId": "server.npcRoles.Template.name",
            "Bold": null,
            "Italic": null,
            "Monospace": null,
            "Underline": null
          }
        },
        "UIComponentList": {},
        "HotbarInventory": {
          "Inventory": {
            "Id": "Simple",
            "Capacity": 3,
            "Items": {}
          },
          "ActiveSlot": 0
        },
        "Transform": {
          "Position": {
            "X": 1.0336036571164788,
            "Y": 12.0,
            "Z": -1.1656590302065126
          },
          "Rotation": {
            "Pitch": 0.0,
            "Yaw": 0.4410141110420227,
            "Roll": 0.0
          }
        },
        "StorageInventory": {
          "Inventory": {
            "Id": "Empty"
          }
        },
        "Velocity": {
          "Velocity": {
            "X": 0.0,
            "Y": 0.0,
            "Z": 0.0
          }
        },
        "PrefabCopyable": {},
        "Interactions": {
          "Interactions": {
            "Use": "*UseNPC"
          }
        },
        "Model": {
          "Model": {
            "Id": "Wind_Sprite",
            "Scale": 1.0022648572921753,
            "Static": false
          }
        },
        "UUID": {
          "UUID": {
            "$binary": "gM2JraizPM2wcQ/Dj0zu7g==",
            "$type": "04"
          }
        },
        "EntityStats": {
          "Version": 5,
          "Stats": {
            "Oxygen": {
              "Id": "Oxygen",
              "Value": 100.0
            },
            "Mana": {
              "Id": "Mana",
              "Value": 0.0
            },
            "Shield": {
              "Id": "Shield",
              "Value": 10.0
            },
            "Health": {
              "Id": "Health",
              "Value": 70.0,
              "Modifiers": {
                "NPC_Max": {
                  "Id": "Static",
                  "CalculationType": "Additive",
                  "Amount": -30.0
                }
              }
            },
            "GlidingActive": {
              "Id": "GlidingActive",
              "Value": 0.0
            },
            "Immunity": {
              "Id": "Immunity",
              "Value": 0.0
            },
            "ShieldActive": {
              "Id": "ShieldActive",
              "Value": 0.0
            },
            "SignatureCharges": {
              "Id": "SignatureCharges",
              "Value": 0.0
            },
            "Stamina": {
              "Id": "Stamina",
              "Value": 10.0
            },
            "Ammo": {
              "Id": "Ammo",
              "Value": 0.0
            },
            "Unknown": {
              "Id": "Unknown",
              "Value": 0.0
            },
            "SignatureEnergy": {
              "Id": "SignatureEnergy",
              "Value": 0.0
            },
            "DeployablePreview": {
              "Id": "DeployablePreview",
              "Value": 0.0
            },
            "StaminaRegenDelay": {
              "Id": "StaminaRegenDelay",
              "Value": 0.0
            },
            "MagicCharges": {
              "Id": "MagicCharges",
              "Value": 0.0
            }
          }
        },
        "NPC": {
          "Version": 5,
          "UUID": {
            "$binary": "gM2JraizPM2wcQ/Dj0zu7g==",
            "$type": "04"
          },
          "Inventory": {
            "Version": 4,
            "ActiveHotbarSlot": 0,
            "ActiveToolsSlot": -1,
            "ActiveUtilitySlot": -1
          },
          "HvrPhs": 0.0,
          "HvrHght": 0.0,
          "MdlScl": 1.0022648572921753,
          "SpawnInstant": "0001-01-03T12:00:00Z",
          "WorldgenId": 0,
          "PathManager": {},
          "LeashPos": {
            "X": -4.490226421944354,
            "Y": 97.0,
            "Z": 81.24926418656928
          },
          "LeashHdg": 3.096343755722046,
          "LeashPtch": 0.0,
          "RoleName": "Wind_Sprite"
        },
        "ArmorInventory": {
          "Inventory": {
            "Id": "Simple",
            "Capacity": 4,
            "Items": {}
          }
        },
        "HeadRotation": {
          "Rotation": {
            "Pitch": 0.0,
            "Yaw": 0.4410141110420227,
            "Roll": 0.0
          }
        }
      }
    },
    {
      "Components": {
        "UtilityInventory": {
          "Inventory": {
            "Id": "Empty"
          },
          "ActiveSlot": -1
        },
        "EffectController": {},
        "DisplayName": {
          "DisplayName": {
            "MessageId": "server.npcRoles.Template.name",
            "Bold": null,
            "Italic": null,
            "Monospace": null,
            "Underline": null
          }
        },
        "UIComponentList": {},
        "HotbarInventory": {
          "Inventory": {
            "Id": "Simple",
            "Capacity": 3,
            "Items": {}
          },
          "ActiveSlot": 0
        },
        "Transform": {
          "Position": {
            "X": 1.2333873932699122,
            "Y": 12.0,
            "Z": 1.3106944729517949
          },
          "Rotation": {
            "Pitch": 0.0,
            "Yaw": 2.364529609680176,
            "Roll": 0.0
          }
        },
        "StorageInventory": {
          "Inventory": {
            "Id": "Empty"
          }
        },
        "Velocity": {
          "Velocity": {
            "X": 0.0,
            "Y": 0.0,
            "Z": 0.0
          }
        },
        "PrefabCopyable": {},
        "Interactions": {
          "Interactions": {
            "Use": "*UseNPC"
          }
        },
        "Model": {
          "Model": {
            "Id": "Wind_Sprite",
            "Scale": 1.0117095708847046,
            "Static": false
          }
        },
        "UUID": {
          "UUID": {
            "$binary": "MXA42g2mM3Kwm+FKSvsuYw==",
            "$type": "04"
          }
        },
        "EntityStats": {
          "Version": 5,
          "Stats": {
            "Oxygen": {
              "Id": "Oxygen",
              "Value": 100.0
            },
            "Mana": {
              "Id": "Mana",
              "Value": 0.0
            },
            "Shield": {
              "Id": "Shield",
              "Value": 10.0
            },
            "Health": {
              "Id": "Health",
              "Value": 70.0,
              "Modifiers": {
                "NPC_Max": {
                  "Id": "Static",
                  "CalculationType": "Additive",
                  "Amount": -30.0
                }
              }
            },
            "GlidingActive": {
              "Id": "GlidingActive",
              "Value": 0.0
            },
            "Immunity": {
              "Id": "Immunity",
              "Value": 0.0
            },
            "ShieldActive": {
              "Id": "ShieldActive",
              "Value": 0.0
            },
            "SignatureCharges": {
              "Id": "SignatureCharges",
              "Value": 0.0
            },
            "Stamina": {
              "Id": "Stamina",
              "Value": 10.0
            },
            "Ammo": {
              "Id": "Ammo",
              "Value": 0.0
            },
            "Unknown": {
              "Id": "Unknown",
              "Value": 0.0
            },
            "SignatureEnergy": {
              "Id": "SignatureEnergy",
              "Value": 0.0
            },
            "DeployablePreview": {
              "Id": "DeployablePreview",
              "Value": 0.0
            },
            "StaminaRegenDelay": {
              "Id": "StaminaRegenDelay",
              "Value": 0.0
            },
            "MagicCharges": {
              "Id": "MagicCharges",
              "Value": 0.0
            }
          }
        },
        "NPC": {
          "Version": 5,
          "UUID": {
            "$binary": "MXA42g2mM3Kwm+FKSvsuYw==",
            "$type": "04"
          },
          "Inventory": {
            "Version": 4,
            "ActiveHotbarSlot": 0,
            "ActiveToolsSlot": -1,
            "ActiveUtilitySlot": -1
          },
          "HvrPhs": 0.0,
          "HvrHght": 0.0,
          "MdlScl": 1.0117095708847046,
          "SpawnInstant": "0001-01-03T12:00:00Z",
          "WorldgenId": 0,
          "PathManager": {},
          "LeashPos": {
            "X": -4.490226421944354,
            "Y": 97.0,
            "Z": 81.24926418656928
          },
          "LeashHdg": 3.096343755722046,
          "LeashPtch": 0.0,
          "RoleName": "Wind_Sprite"
        },
        "ArmorInventory": {
          "Inventory": {
            "Id": "Simple",
            "Capacity": 4,
            "Items": {}
          }
        },
        "HeadRotation": {
          "Rotation": {
            "Pitch": 0.0,
            "Yaw": 2.364529609680176,
            "Roll": 0.0
          }
        }
      }
    },
    {
      "Components": {
        "UtilityInventory": {
          "Inventory": {
            "Id": "Empty"
          },
          "ActiveSlot": -1
        },
        "EffectController": {},
        "DisplayName": {
          "DisplayName": {
            "MessageId": "server.npcRoles.Template.name",
            "Bold": null,
            "Italic": null,
            "Monospace": null,
            "Underline": null
          }
        },
        "UIComponentList": {},
        "HotbarInventory": {
          "Inventory": {
            "Id": "Simple",
            "Capacity": 3,
            "Items": {}
          },
          "ActiveSlot": 0
        },
        "Transform": {
          "Position": {
            "X": 0.350847005409328,
            "Y": 13.0,
            "Z": 0.013233573903832507
          },
          "Rotation": {
            "Pitch": 0.0,
            "Yaw": 1.2636626958847046,
            "Roll": 0.0
          }
        },
        "StorageInventory": {
          "Inventory": {
            "Id": "Empty"
          }
        },
        "Velocity": {
          "Velocity": {
            "X": 0.0,
            "Y": 0.0,
            "Z": 0.0
          }
        },
        "PrefabCopyable": {},
        "Interactions": {
          "Interactions": {
            "Use": "*UseNPC"
          }
        },
        "Model": {
          "Model": {
            "Id": "Wind_Sprite",
            "Scale": 0.9581310153007507,
            "Static": false
          }
        },
        "UUID": {
          "UUID": {
            "$binary": "qYc40E3gP0itgX/6dmlQNQ==",
            "$type": "04"
          }
        },
        "EntityStats": {
          "Version": 5,
          "Stats": {
            "Oxygen": {
              "Id": "Oxygen",
              "Value": 100.0
            },
            "Mana": {
              "Id": "Mana",
              "Value": 0.0
            },
            "Shield": {
              "Id": "Shield",
              "Value": 10.0
            },
            "Health": {
              "Id": "Health",
              "Value": 70.0,
              "Modifiers": {
                "NPC_Max": {
                  "Id": "Static",
                  "CalculationType": "Additive",
                  "Amount": -30.0
                }
              }
            },
            "GlidingActive": {
              "Id": "GlidingActive",
              "Value": 0.0
            },
            "Immunity": {
              "Id": "Immunity",
              "Value": 0.0
            },
            "ShieldActive": {
              "Id": "ShieldActive",
              "Value": 0.0
            },
            "SignatureCharges": {
              "Id": "SignatureCharges",
              "Value": 0.0
            },
            "Stamina": {
              "Id": "Stamina",
              "Value": 10.0
            },
            "Ammo": {
              "Id": "Ammo",
              "Value": 0.0
            },
            "Unknown": {
              "Id": "Unknown",
              "Value": 0.0
            },
            "SignatureEnergy": {
              "Id": "SignatureEnergy",
              "Value": 0.0
            },
            "DeployablePreview": {
              "Id": "DeployablePreview",
              "Value": 0.0
            },
            "StaminaRegenDelay": {
              "Id": "StaminaRegenDelay",
              "Value": 0.0
            },
            "MagicCharges": {
              "Id": "MagicCharges",
              "Value": 0.0
            }
          }
        },
        "NPC": {
          "Version": 5,
          "UUID": {
            "$binary": "qYc40E3gP0itgX/6dmlQNQ==",
            "$type": "04"
          },
          "Inventory": {
            "Version": 4,
            "ActiveHotbarSlot": 0,
            "ActiveToolsSlot": -1,
            "ActiveUtilitySlot": -1
          },
          "HvrPhs": 0.0,
          "HvrHght": 0.0,
          "MdlScl": 0.9581310153007507,
          "SpawnInstant": "0001-01-03T12:00:00Z",
          "WorldgenId": 0,
          "PathManager": {},
          "LeashPos": {
            "X": -4.490226421944354,
            "Y": 97.0,
            "Z": 81.24926418656928
          },
          "LeashHdg": 3.096343755722046,
          "LeashPtch": 0.0,
          "RoleName": "Wind_Sprite"
        },
        "ArmorInventory": {
          "Inventory": {
            "Id": "Simple",
            "Capacity": 4,
            "Items": {}
          }
        },
        "HeadRotation": {
          "Rotation": {
            "Pitch": 0.0,
            "Yaw": 1.2636626958847046,
            "Roll": 0.0
          }
        }
      }
    },
    {
      "Components": {
        "Nameplate": {
          "Text": "Wind_Sprite"
        },
        "HiddenFromAdventurePlayer": {},
        "RefId": {
          "Count": 0
        },
        "SpawnMarkerComponent": {
          "SpawnMarker": "Wind_Sprite",
          "RespawnTime": 0.0,
          "SpawnCount": 1,
          "GameTimeRespawn": "PT24H",
          "NPCReferences": [
            {
              "UUID": {
                "$binary": "P4lfQU9ENyOoIt104ohIxQ==",
                "$type": "04"
              },
              "RefCount": 0
            }
          ],
          "PersistedFlock": {},
          "SpawnPosition": {
            "X": -5.5,
            "Y": 98.0,
            "Z": 81.5
          }
        },
        "Transform": {
          "Position": {
            "X": 0.5,
            "Y": 13.0,
            "Z": 0.5
          },
          "Rotation": {
            "Pitch": 0.0,
            "Yaw": 0.0,
            "Roll": 0.0
          }
        },
        "Intangible": {},
        "PrefabCopyable": {},
        "Model": {
          "Model": {
            "Id": "NPC_Spawn_Marker",
            "Scale": 1.0,
            "Static": false
          }
        },
        "UUID": {
          "UUID": {
            "$binary": "A6avU+scM9qxoVfvC6zE1Q==",
            "$type": "04"
          }
        },
        "SpawnMarkerBlockReference": {
          "BlockPosition": {
            "X": -6,
            "Y": 97,
            "Z": 81
          }
        }
      }
    }
  ]
}