{
  "version": 8,
  "blockIdVersion": 11,
  "anchorX": 0,
  "anchorY": 0,
  "anchorZ": 0,
  "blocks": [
    {
      "x": -4,
      "y": 0,
      "z": -2,
      "name": "Rock_Calcite_Brick_Smooth_Half",
      "rotation": 8
    },
    {
      "x": -4,
      "y": 18,
      "z": -2,
      "name": "Rock_Calcite_Brick_Smooth_Half",
      "rotation": 34
    },
    {
      "x": -4,
      "y": 1,
      "z": 0,
      "name": "Rock_Calcite_Brick_Smooth_Half",
      "rotation": 35
    },
    {
      "x": -4,
      "y": 2,
      "z": 0,
      "name": "Rock_Crystal_Wind_Small"
    },
    {
      "x": -4,
      "y": 19,
      "z": 0,
      "name": "Rock_Calcite_Brick_Smooth_Half",
      "rotation": 35
    },
    {
      "x": -4,
      "y": 20,
      "z": 2,
      "name": "Rock_Calcite_Brick_Smooth_Half",
      "rotation": 8
    },
    {
      "x": -4,
      "y": 21,
      "z": 2,
      "name": "Rock_Crystal_Wind_Small"
    },
    {
      "x": -3,
      "y": 22,
      "z": 0,
      "name": "Rock_Crystal_Wind_Small",
      "rotation": 7
    },
    {
      "x": -3,
      "y": 23,
      "z": 0,
      "name": "Rock_Crystal_Wind_Medium",
      "rotation": 7
    },
    {
      "x": -3,
      "y": 24,
      "z": 0,
      "name": "Rock_Crystal_Wind_Large",
      "rotation": 7
    },
    {
      "x": -3,
      "y": 25,
      "z": 0,
      "name": "Rock_Calcite_Brick_Roof_Hollow",
      "rotation": 1
    },
    {
      "x": -2,
      "y": -2,
      "z": -4,
      "name": "Rock_Calcite_Brick_Smooth_Half",
      "rotation": 8
    },
    {
      "x": -2,
      "y": 16,
      "z": -4,
      "name": "Rock_Calcite_Brick_Smooth_Half",
      "rotation": 34
    },
    {
      "x": -2,
      "y": -1,
      "z": -2,
      "name": "Rock_Calcite_Brick_Smooth_Half",
      "rotation": 8
    },
    {
      "x": -2,
      "y": 17,
      "z": -2,
      "name": "Rock_Calcite_Brick_Smooth_Half",
      "rotation": 34
    },
    {
      "x": -2,
      "y": 22,
      "z": -1,
      "name": "Rock_Calcite_Brick_Smooth_Half",
      "rotation": 8
    },
    {
      "x": -2,
      "y": 23,
      "z": -1,
      "name": "Rock_Crystal_Wind_Small"
    },
    {
      "x": -2,
      "y": 2,
      "z": 0,
      "name": "Rock_Calcite_Brick_Smooth_Half",
      "rotation": 35
    },
    {
      "x": -2,
      "y": 21,
      "z": 0,
      "name": "Rock_Crystal_Wind_Small",
      "rotation": 8
    },
    {
      "x": -2,
      "y": 22,
      "z": 0,
      "name": "*Rock_Calcite_Brick_Smooth_Half_State_Definitions_Block",
      "rotation": 8
    },
    {
      "x": -2,
      "y": 23,
      "z": 0,
      "name": "Rock_Calcite_Brick_Roof_Steep",
      "rotation": 1
    },
    {
      "x": -2,
      "y": 24,
      "z": 0,
      "name": "Rock_Calcite_Brick_Roof_Steep",
      "filler": 1024,
      "rotation": 1
    },
    {
      "x": -2,
      "y": 22,
      "z": 1,
      "name": "Rock_Calcite_Brick_Smooth_Half",
      "rotation": 8
    },
    {
      "x": -2,
      "y": 23,
      "z": 1,
      "name": "Rock_Crystal_Wind_Small"
    },
    {
      "x": -2,
      "y": 3,
      "z": 2,
      "name": "Rock_Calcite_Brick_Smooth_Half",
      "rotation": 35
    },
    {
      "x": -2,
      "y": 21,
      "z": 2,
      "name": "Rock_Calcite_Brick_Smooth_Half",
      "rotation": 35
    },
    {
      "x": -2,
      "y": 4,
      "z": 4,
      "name": "Rock_Calcite_Brick_Smooth_Half",
      "rotation": 35
    },
    {
      "x": -1,
      "y": 22,
      "z": -2,
      "name": "Rock_Calcite_Brick_Smooth_Half",
      "rotation": 8
    },
    {
      "x": -1,
      "y": 23,
      "z": -2,
      "name": "Rock_Crystal_Wind_Small"
    },
    {
      "x": -1,
      "y": 22,
      "z": -1,
      "name": "*Rock_Calcite_Brick_Stairs_State_Definitions_Corner_Left",
      "rotation": 9
    },
    {
      "x": -1,
      "y": 23,
      "z": -1,
      "name": "Rock_Gem_Aquamarine"
    },
    {
      "x": -1,
      "y": 22,
      "z": 0,
      "name": "Rock_Calcite_Brick_Stairs",
      "rotation": 9
    },
    {
      "x": -1,
      "y": 22,
      "z": 1,
      "name": "*Rock_Calcite_Brick_Stairs_State_Definitions_Corner_Left",
      "rotation": 10
    },
    {
      "x": 0,
      "y": 15,
      "z": -4,
      "name": "Rock_Calcite_Brick_Smooth_Half",
      "rotation": 33
    },
    {
      "x": 0,
      "y": 16,
      "z": -4,
      "name": "Rock_Crystal_Wind_Small"
    },
    {
      "x": 0,
      "y": 22,
      "z": -3,
      "name": "Rock_Crystal_Wind_Small",
      "rotation": 6
    },
    {
      "x": 0,
      "y": 23,
      "z": -3,
      "name": "Rock_Crystal_Wind_Medium",
      "rotation": 6
    },
    {
      "x": 0,
      "y": 24,
      "z": -3,
      "name": "Rock_Crystal_Wind_Large",
      "rotation": 6
    },
    {
      "x": 0,
      "y": 25,
      "z": -3,
      "name": "Rock_Calcite_Brick_Roof_Hollow"
    },
    {
      "x": 0,
      "y": 14,
      "z": -2,
      "name": "Rock_Calcite_Brick_Smooth_Half",
      "rotation": 33
    },
    {
      "x": 0,
      "y": 21,
      "z": -2,
      "name": "Rock_Crystal_Wind_Small",
      "rotation": 8
    },
    {
      "x": 0,
      "y": 22,
      "z": -2,
      "name": "*Rock_Calcite_Brick_Smooth_Half_State_Definitions_Block",
      "rotation": 8
    },
    {
      "x": 0,
      "y": 23,
      "z": -2,
      "name": "Rock_Calcite_Brick_Roof_Steep"
    },
    {
      "x": 0,
      "y": 24,
      "z": -2,
      "name": "Rock_Calcite_Brick_Roof_Steep",
      "filler": 1024
    },
    {
      "x": 0,
      "y": 22,
      "z": -1,
      "name": "Rock_Calcite_Brick_Stairs",
      "rotation": 8
    },
    {
      "x": 0,
      "y": -5,
      "z": 0,
      "name": "Rock_Calcite_Brick_Smooth"
    },
    {
      "x": 0,
      "y": -4,
      "z": 0,
      "name": "Rock_Calcite_Brick_Smooth"
    },
    {
      "x": 0,
      "y": -3,
      "z": 0,
      "name": "Rock_Calcite_Brick_Smooth"
    },
    {
      "x": 0,
      "y": -2,
      "z": 0,
      "name": "Rock_Calcite_Brick_Smooth"
    },
    {
      "x": 0,
      "y": -1,
      "z": 0,
      "name": "Rock_Calcite_Brick_Smooth"
    },
    {
      "x": 0,
      "y": 0,
      "z": 0,
      "name": "Rock_Calcite_Brick_Pillar_Base"
    },
    {
      "x": 0,
      "y": 1,
      "z": 0,
      "name": "Rock_Calcite_Brick_Pillar_Base"
    },
    {
      "x": 0,
      "y": 2,
      "z": 0,
      "name": "Rock_Calcite_Brick_Pillar_Middle"
    },
    {
      "x": 0,
      "y": 3,
      "z": 0,
      "name": "Rock_Calcite_Brick_Pillar_Middle"
    },
    {
      "x": 0,
      "y": 4,
      "z": 0,
      "name": "Rock_Calcite_Brick_Pillar_Middle"
    },
    {
      "x": 0,
      "y": 5,
      "z": 0,
      "name": "Rock_Calcite_Brick_Pillar_Middle"
    },
    {
      "x": 0,
      "y": 6,
      "z": 0,
      "name": "Rock_Calcite_Brick_Pillar_Middle"
    },
    {
      "x": 0,
      "y": 7,
      "z": 0,
      "name": "Rock_Calcite_Brick_Pillar_Middle"
    },
    {
      "x": 0,
      "y": 8,
      "z": 0,
      "name": "Rock_Calcite_Brick_Pillar_Middle"
    },
    {
      "x": 0,
      "y": 9,
      "z": 0,
      "name": "Rock_Calcite_Brick_Pillar_Middle"
    },
    {
      "x": 0,
      "y": 10,
      "z": 0,
      "name": "Rock_Calcite_Brick_Pillar_Middle"
    },
    {
      "x": 0,
      "y": 11,
      "z": 0,
      "name": "Rock_Calcite_Brick_Pillar_Middle"
    },
    {
      "x": 0,
      "y": 12,
      "z": 0,
      "name": "Rock_Calcite_Brick_Pillar_Middle"
    },
    {
      "x": 0,
      "y": 13,
      "z": 0,
      "name": "Rock_Calcite_Brick_Pillar_Base",
      "rotation": 8
    },
    {
      "x": 0,
      "y": 14,
      "z": 0,
      "name": "Rock_Crystal_Wind_Large"
    },
    {
      "x": 0,
      "y": 15,
      "z": 0,
      "name": "Rock_Calcite_Brick_Pillar_Base"
    },
    {
      "x": 0,
      "y": 16,
      "z": 0,
      "name": "Rock_Calcite_Brick_Pillar_Middle"
    },
    {
      "x": 0,
      "y": 17,
      "z": 0,
      "name": "Rock_Calcite_Brick_Pillar_Middle"
    },
    {
      "x": 0,
      "y": 18,
      "z": 0,
      "name": "Rock_Calcite_Brick_Pillar_Middle"
    },
    {
      "x": 0,
      "y": 19,
      "z": 0,
      "name": "Rock_Calcite_Brick_Pillar_Middle"
    },
    {
      "x": 0,
      "y": 20,
      "z": 0,
      "name": "Rock_Calcite_Brick_Pillar_Middle"
    },
    {
      "x": 0,
      "y": 21,
      "z": 0,
      "name": "Rock_Calcite_Brick_Pillar_Base",
      "rotation": 8
    },
    {
      "x": 0,
      "y": 22,
      "z": 0,
      "name": "Spawner_Wind_Sprite",
      "components": {
        "Components": {
          "PlacedByInteraction": {
            "WhoPlacedUuid": {
              "$binary": "bqDSATiwT++EkU6x0gHadg==",
              "$type": "04"
            }
          },
          "SpawnMarkerBlock": {
            "MarkerReference": {
              "UUID": {
                "$binary": "iK1SSHKmOGm+YK0DXTBdQw==",
                "$type": "04"
              }
            }
          }
        }
      }
    },
    {
      "x": 0,
      "y": 22,
      "z": 1,
      "name": "Rock_Calcite_Brick_Stairs",
      "rotation": 10
    },
    {
      "x": 0,
      "y": 21,
      "z": 2,
      "name": "Rock_Crystal_Wind_Small",
      "rotation": 8
    },
    {
      "x": 0,
      "y": 22,
      "z": 2,
      "name": "*Rock_Calcite_Brick_Smooth_Half_State_Definitions_Block",
      "rotation": 8
    },
    {
      "x": 0,
      "y": 23,
      "z": 2,
      "name": "Rock_Calcite_Brick_Roof_Steep",
      "rotation": 2
    },
    {
      "x": 0,
      "y": 24,
      "z": 2,
      "name": "Rock_Calcite_Brick_Roof_Steep",
      "filler": 1024,
      "rotation": 2
    },
    {
      "x": 0,
      "y": 22,
      "z": 3,
      "name": "Rock_Crystal_Wind_Small",
      "rotation": 4
    },
    {
      "x": 0,
      "y": 23,
      "z": 3,
      "name": "Rock_Crystal_Wind_Medium",
      "rotation": 4
    },
    {
      "x": 0,
      "y": 24,
      "z": 3,
      "name": "Rock_Crystal_Wind_Large",
      "rotation": 4
    },
    {
      "x": 0,
      "y": 25,
      "z": 3,
      "name": "Rock_Calcite_Brick_Roof_Hollow",
      "rotation": 2
    },
    {
      "x": 0,
      "y": 5,
      "z": 4,
      "name": "Rock_Calcite_Brick_Smooth_Half",
      "rotation": 35
    },
    {
      "x": 0,
      "y": 6,
      "z": 6,
      "name": "Rock_Calcite_Brick_Smooth_Half",
      "rotation": 35
    },
    {
      "x": 0,
      "y": 7,
      "z": 6,
      "name": "Rock_Crystal_Wind_Small"
    },
    {
      "x": 1,
      "y": 22,
      "z": -2,
      "name": "Rock_Calcite_Brick_Smooth_Half",
      "rotation": 8
    },
    {
      "x": 1,
      "y": 23,
      "z": -2,
      "name": "Rock_Crystal_Wind_Small"
    },
    {
      "x": 1,
      "y": 22,
      "z": -1,
      "name": "*Rock_Calcite_Brick_Stairs_State_Definitions_Corner_Left",
      "rotation": 8
    },
    {
      "x": 1,
      "y": 23,
      "z": -1,
      "name": "Rock_Crystal_Wind_Large"
    },
    {
      "x": 1,
      "y": 22,
      "z": 0,
      "name": "Rock_Calcite_Brick_Stairs",
      "rotation": 11
    },
    {
      "x": 1,
      "y": 22,
      "z": 1,
      "name": "*Rock_Calcite_Brick_Stairs_State_Definitions_Corner_Left",
      "rotation": 11
    },
    {
      "x": 1,
      "y": 23,
      "z": 1,
      "name": "Rock_Gem_Aquamarine"
    },
    {
      "x": 1,
      "y": 22,
      "z": 2,
      "name": "Rock_Calcite_Brick_Smooth_Half",
      "rotation": 8
    },
    {
      "x": 1,
      "y": 23,
      "z": 2,
      "name": "Rock_Crystal_Wind_Small"
    },
    {
      "x": 2,
      "y": 13,
      "z": -2,
      "name": "Rock_Calcite_Brick_Smooth_Half",
      "rotation": 33
    },
    {
      "x": 2,
      "y": 22,
      "z": -1,
      "name": "Rock_Calcite_Brick_Smooth_Half",
      "rotation": 8
    },
    {
      "x": 2,
      "y": 23,
      "z": -1,
      "name": "Rock_Crystal_Wind_Small"
    },
    {
      "x": 2,
      "y": 12,
      "z": 0,
      "name": "Rock_Calcite_Brick_Smooth_Half",
      "rotation": 33
    },
    {
      "x": 2,
      "y": 21,
      "z": 0,
      "name": "Rock_Crystal_Wind_Small",
      "rotation": 8
    },
    {
      "x": 2,
      "y": 22,
      "z": 0,
      "name": "*Rock_Calcite_Brick_Smooth_Half_State_Definitions_Block",
      "rotation": 8
    },
    {
      "x": 2,
      "y": 23,
      "z": 0,
      "name": "Rock_Calcite_Brick_Roof_Steep",
      "rotation": 3
    },
    {
      "x": 2,
      "y": 24,
      "z": 0,
      "name": "Rock_Calcite_Brick_Roof_Steep",
      "filler": 1024,
      "rotation": 3
    },
    {
      "x": 2,
      "y": 22,
      "z": 1,
      "name": "Rock_Calcite_Brick_Smooth_Half",
      "rotation": 8
    },
    {
      "x": 2,
      "y": 23,
      "z": 1,
      "name": "Rock_Crystal_Wind_Small"
    },
    {
      "x": 2,
      "y": 11,
      "z": 2,
      "name": "Rock_Calcite_Brick_Smooth_Half",
      "rotation": 33
    },
    {
      "x": 2,
      "y": 12,
      "z": 2,
      "name": "Rock_Crystal_Wind_Small"
    },
    {
      "x": 2,
      "y": 8,
      "z": 4,
      "name": "Rock_Calcite_Brick_Smooth_Half",
      "rotation": 32
    },
    {
      "x": 2,
      "y": 7,
      "z": 6,
      "name": "Rock_Calcite_Brick_Smooth_Half",
      "rotation": 32
    },
    {
      "x": 3,
      "y": 22,
      "z": 0,
      "name": "Rock_Crystal_Wind_Small",
      "rotation": 5
    },
    {
      "x": 3,
      "y": 23,
      "z": 0,
      "name": "Rock_Crystal_Wind_Medium",
      "rotation": 5
    },
    {
      "x": 3,
      "y": 24,
      "z": 0,
      "name": "Rock_Crystal_Wind_Large",
      "rotation": 5
    },
    {
      "x": 3,
      "y": 25,
      "z": 0,
      "name": "Rock_Calcite_Brick_Roof_Hollow",
      "rotation": 3
    },
    {
      "x": 4,
      "y": 10,
      "z": 2,
      "name": "Rock_Calcite_Brick_Smooth_Half",
      "rotation": 33
    },
    {
      "x": 4,
      "y": 9,
      "z": 4,
      "name": "Rock_Calcite_Brick_Smooth_Half",
      "rotation": 32
    }
  ]
}