{
  "version": 8,
  "blockIdVersion": 11,
  "anchorX": 0,
  "anchorY": 0,
  "anchorZ": 0,
  "blocks": [
    {
      "x": -5,
      "y": 18,
      "z": -1,
      "name": "*Rock_Calcite_Brick_Stairs_State_Definitions_Corner_Right",
      "rotation": 8
    },
    {
      "x": -5,
      "y": 18,
      "z": 0,
      "name": "Rock_Calcite_Brick_Stairs",
      "rotation": 9
    },
    {
      "x": -5,
      "y": 18,
      "z": 1,
      "name": "*Rock_Calcite_Brick_Stairs_State_Definitions_Corner_Left",
      "rotation": 10
    },
    {
      "x": -4,
      "y": 26,
      "z": -3,
      "name": "Rock_Calcite_Brick_Roof_Hollow"
    },
    {
      "x": -4,
      "y": 25,
      "z": -2,
      "name": "Rock_Calcite_Brick_Roof_Hollow"
    },
    {
      "x": -4,
      "y": 18,
      "z": -1,
      "name": "Rock_Calcite_Brick_Stairs",
      "rotation": 8
    },
    {
      "x": -4,
      "y": 22,
      "z": -1,
      "name": "Rock_Calcite_Brick_Half",
      "rotation": 6
    },
    {
      "x": -4,
      "y": 23,
      "z": -1,
      "name": "Rock_Calcite_Brick_Roof_Steep"
    },
    {
      "x": -4,
      "y": 24,
      "z": -1,
      "name": "Rock_Calcite_Brick_Roof_Steep",
      "filler": 1024
    },
    {
      "x": -4,
      "y": -5,
      "z": 0,
      "name": "Rock_Calcite_Brick_Smooth"
    },
    {
      "x": -4,
      "y": -4,
      "z": 0,
      "name": "Rock_Calcite_Brick_Smooth"
    },
    {
      "x": -4,
      "y": -3,
      "z": 0,
      "name": "Rock_Calcite_Brick_Smooth"
    },
    {
      "x": -4,
      "y": -2,
      "z": 0,
      "name": "Rock_Calcite_Brick_Smooth"
    },
    {
      "x": -4,
      "y": -1,
      "z": 0,
      "name": "Rock_Calcite_Brick_Smooth"
    },
    {
      "x": -4,
      "y": 0,
      "z": 0,
      "name": "Rock_Calcite_Brick_Smooth"
    },
    {
      "x": -4,
      "y": 1,
      "z": 0,
      "name": "Rock_Calcite_Brick_Pillar_Base"
    },
    {
      "x": -4,
      "y": 2,
      "z": 0,
      "name": "Rock_Calcite_Brick_Pillar_Middle",
      "rotation": 8
    },
    {
      "x": -4,
      "y": 3,
      "z": 0,
      "name": "Rock_Calcite_Brick_Pillar_Middle",
      "rotation": 8
    },
    {
      "x": -4,
      "y": 4,
      "z": 0,
      "name": "Rock_Calcite_Brick_Pillar_Middle",
      "rotation": 8
    },
    {
      "x": -4,
      "y": 5,
      "z": 0,
      "name": "Rock_Calcite_Brick_Pillar_Middle",
      "rotation": 8
    },
    {
      "x": -4,
      "y": 6,
      "z": 0,
      "name": "Rock_Calcite_Brick_Pillar_Middle",
      "rotation": 8
    },
    {
      "x": -4,
      "y": 7,
      "z": 0,
      "name": "Rock_Calcite_Brick_Pillar_Middle",
      "rotation": 8
    },
    {
      "x": -4,
      "y": 8,
      "z": 0,
      "name": "Rock_Calcite_Brick_Pillar_Base",
      "rotation": 8
    },
    {
      "x": -4,
      "y": 9,
      "z": 0,
      "name": "Rock_Crystal_Wind_Large"
    },
    {
      "x": -4,
      "y": 10,
      "z": 0,
      "name": "Rock_Calcite_Brick_Pillar_Base"
    },
    {
      "x": -4,
      "y": 11,
      "z": 0,
      "name": "Rock_Calcite_Brick_Pillar_Middle",
      "rotation": 8
    },
    {
      "x": -4,
      "y": 12,
      "z": 0,
      "name": "Rock_Calcite_Brick_Pillar_Middle",
      "rotation": 8
    },
    {
      "x": -4,
      "y": 13,
      "z": 0,
      "name": "Rock_Calcite_Brick_Pillar_Middle",
      "rotation": 8
    },
    {
      "x": -4,
      "y": 14,
      "z": 0,
      "name": "Rock_Calcite_Brick_Pillar_Middle",
      "rotation": 8
    },
    {
      "x": -4,
      "y": 15,
      "z": 0,
      "name": "Rock_Calcite_Brick_Pillar_Middle"
    },
    {
      "x": -4,
      "y": 16,
      "z": 0,
      "name": "Rock_Calcite_Brick_Pillar_Middle"
    },
    {
      "x": -4,
      "y": 17,
      "z": 0,
      "name": "Rock_Calcite_Brick_Pillar_Base",
      "rotation": 8
    },
    {
      "x": -4,
      "y": 18,
      "z": 0,
      "name": "Rock_Calcite_Brick_Smooth"
    },
    {
      "x": -4,
      "y": 19,
      "z": 0,
      "name": "Rock_Crystal_Wind_Large",
      "rotation": 11
    },
    {
      "x": -4,
      "y": 20,
      "z": 0,
      "name": "Rock_Calcite_Brick_Pillar_Base",
      "rotation": 3
    },
    {
      "x": -4,
      "y": 21,
      "z": 0,
      "name": "Rock_Calcite_Brick_Pillar_Base",
      "rotation": 11
    },
    {
      "x": -4,
      "y": 22,
      "z": 0,
      "name": "Rock_Calcite_Brick_Ornate",
      "rotation": 3
    },
    {
      "x": -4,
      "y": 24,
      "z": 0,
      "name": "Rock_Calcite_Brick_Wall",
      "rotation": 3
    },
    {
      "x": -4,
      "y": 18,
      "z": 1,
      "name": "Rock_Calcite_Brick_Stairs",
      "rotation": 10
    },
    {
      "x": -4,
      "y": 22,
      "z": 1,
      "name": "Rock_Calcite_Brick_Half",
      "rotation": 4
    },
    {
      "x": -4,
      "y": 23,
      "z": 1,
      "name": "Rock_Calcite_Brick_Roof_Steep",
      "rotation": 2
    },
    {
      "x": -4,
      "y": 24,
      "z": 1,
      "name": "Rock_Calcite_Brick_Roof_Steep",
      "filler": 1024,
      "rotation": 2
    },
    {
      "x": -4,
      "y": 25,
      "z": 2,
      "name": "Rock_Calcite_Brick_Roof_Hollow",
      "rotation": 2
    },
    {
      "x": -4,
      "y": 26,
      "z": 3,
      "name": "Rock_Calcite_Brick_Roof_Hollow",
      "rotation": 2
    },
    {
      "x": -3,
      "y": 26,
      "z": -4,
      "name": "Rock_Calcite_Brick_Roof_Hollow",
      "rotation": 1
    },
    {
      "x": -3,
      "y": 18,
      "z": -1,
      "name": "*Rock_Calcite_Brick_Stairs_State_Definitions_Corner_Left",
      "rotation": 8
    },
    {
      "x": -3,
      "y": 18,
      "z": 0,
      "name": "Rock_Calcite_Brick_Stairs",
      "rotation": 11
    },
    {
      "x": -3,
      "y": 18,
      "z": 1,
      "name": "*Rock_Calcite_Brick_Stairs_State_Definitions_Corner_Right",
      "rotation": 10
    },
    {
      "x": -3,
      "y": 26,
      "z": 4,
      "name": "Rock_Calcite_Brick_Roof_Hollow",
      "rotation": 1
    },
    {
      "x": -2,
      "y": 25,
      "z": -4,
      "name": "Rock_Calcite_Brick_Roof_Hollow",
      "rotation": 1
    },
    {
      "x": -2,
      "y": 25,
      "z": 4,
      "name": "Rock_Calcite_Brick_Roof_Hollow",
      "rotation": 1
    },
    {
      "x": -1,
      "y": 18,
      "z": -5,
      "name": "*Rock_Calcite_Brick_Stairs_State_Definitions_Corner_Left",
      "rotation": 9
    },
    {
      "x": -1,
      "y": 18,
      "z": -4,
      "name": "Rock_Calcite_Brick_Stairs",
      "rotation": 9
    },
    {
      "x": -1,
      "y": 22,
      "z": -4,
      "name": "Rock_Calcite_Brick_Half",
      "rotation": 7
    },
    {
      "x": -1,
      "y": 23,
      "z": -4,
      "name": "Rock_Calcite_Brick_Roof_Steep",
      "rotation": 1
    },
    {
      "x": -1,
      "y": 24,
      "z": -4,
      "name": "Rock_Calcite_Brick_Roof_Steep",
      "filler": 1024,
      "rotation": 1
    },
    {
      "x": -1,
      "y": 18,
      "z": -3,
      "name": "*Rock_Calcite_Brick_Stairs_State_Definitions_Corner_Right",
      "rotation": 9
    },
    {
      "x": -1,
      "y": 21,
      "z": 0,
      "name": "Rock_Crystal_Wind_Small",
      "rotation": 7
    },
    {
      "x": -1,
      "y": 22,
      "z": 0,
      "name": "Rock_Crystal_Wind_Large",
      "rotation": 7
    },
    {
      "x": -1,
      "y": 23,
      "z": 0,
      "name": "Rock_Crystal_Wind_Small",
      "rotation": 7
    },
    {
      "x": -1,
      "y": 18,
      "z": 3,
      "name": "*Rock_Calcite_Brick_Stairs_State_Definitions_Corner_Left",
      "rotation": 9
    },
    {
      "x": -1,
      "y": 18,
      "z": 4,
      "name": "Rock_Calcite_Brick_Stairs",
      "rotation": 9
    },
    {
      "x": -1,
      "y": 22,
      "z": 4,
      "name": "Rock_Calcite_Brick_Half",
      "rotation": 7
    },
    {
      "x": -1,
      "y": 23,
      "z": 4,
      "name": "Rock_Calcite_Brick_Roof_Steep",
      "rotation": 1
    },
    {
      "x": -1,
      "y": 24,
      "z": 4,
      "name": "Rock_Calcite_Brick_Roof_Steep",
      "filler": 1024,
      "rotation": 1
    },
    {
      "x": -1,
      "y": 18,
      "z": 5,
      "name": "*Rock_Calcite_Brick_Stairs_State_Definitions_Corner_Left",
      "rotation": 10
    },
    {
      "x": 0,
      "y": 18,
      "z": -5,
      "name": "Rock_Calcite_Brick_Stairs",
      "rotation": 8
    },
    {
      "x": 0,
      "y": -5,
      "z": -4,
      "name": "Rock_Calcite_Brick_Smooth"
    },
    {
      "x": 0,
      "y": -4,
      "z": -4,
      "name": "Rock_Calcite_Brick_Smooth"
    },
    {
      "x": 0,
      "y": -3,
      "z": -4,
      "name": "Rock_Calcite_Brick_Smooth"
    },
    {
      "x": 0,
      "y": -2,
      "z": -4,
      "name": "Rock_Calcite_Brick_Smooth"
    },
    {
      "x": 0,
      "y": -1,
      "z": -4,
      "name": "Rock_Calcite_Brick_Smooth"
    },
    {
      "x": 0,
      "y": 0,
      "z": -4,
      "name": "Rock_Calcite_Brick_Smooth"
    },
    {
      "x": 0,
      "y": 1,
      "z": -4,
      "name": "Rock_Calcite_Brick_Pillar_Base"
    },
    {
      "x": 0,
      "y": 2,
      "z": -4,
      "name": "Rock_Calcite_Brick_Pillar_Middle",
      "rotation": 8
    },
    {
      "x": 0,
      "y": 3,
      "z": -4,
      "name": "Rock_Calcite_Brick_Pillar_Middle",
      "rotation": 8
    },
    {
      "x": 0,
      "y": 4,
      "z": -4,
      "name": "Rock_Calcite_Brick_Pillar_Middle",
      "rotation": 8
    },
    {
      "x": 0,
      "y": 5,
      "z": -4,
      "name": "Rock_Calcite_Brick_Pillar_Middle",
      "rotation": 8
    },
    {
      "x": 0,
      "y": 6,
      "z": -4,
      "name": "Rock_Calcite_Brick_Pillar_Middle",
      "rotation": 8
    },
    {
      "x": 0,
      "y": 7,
      "z": -4,
      "name": "Rock_Calcite_Brick_Pillar_Middle",
      "rotation": 8
    },
    {
      "x": 0,
      "y": 8,
      "z": -4,
      "name": "Rock_Calcite_Brick_Pillar_Base",
      "rotation": 8
    },
    {
      "x": 0,
      "y": 9,
      "z": -4,
      "name": "Rock_Crystal_Wind_Large"
    },
    {
      "x": 0,
      "y": 10,
      "z": -4,
      "name": "Rock_Calcite_Brick_Pillar_Base"
    },
    {
      "x": 0,
      "y": 11,
      "z": -4,
      "name": "Rock_Calcite_Brick_Pillar_Middle",
      "rotation": 8
    },
    {
      "x": 0,
      "y": 12,
      "z": -4,
      "name": "Rock_Calcite_Brick_Pillar_Middle",
      "rotation": 8
    },
    {
      "x": 0,
      "y": 13,
      "z": -4,
      "name": "Rock_Calcite_Brick_Pillar_Middle",
      "rotation": 8
    },
    {
      "x": 0,
      "y": 14,
      "z": -4,
      "name": "Rock_Calcite_Brick_Pillar_Middle",
      "rotation": 8
    },
    {
      "x": 0,
      "y": 15,
      "z": -4,
      "name": "Rock_Calcite_Brick_Pillar_Middle"
    },
    {
      "x": 0,
      "y": 16,
      "z": -4,
      "name": "Rock_Calcite_Brick_Pillar_Middle"
    },
    {
      "x": 0,
      "y": 17,
      "z": -4,
      "name": "Rock_Calcite_Brick_Pillar_Base",
      "rotation": 8
    },
    {
      "x": 0,
      "y": 18,
      "z": -4,
      "name": "Rock_Calcite_Brick_Smooth"
    },
    {
      "x": 0,
      "y": 19,
      "z": -4,
      "name": "Rock_Crystal_Wind_Large",
      "rotation": 8
    },
    {
      "x": 0,
      "y": 20,
      "z": -4,
      "name": "Rock_Calcite_Brick_Pillar_Base"
    },
    {
      "x": 0,
      "y": 21,
      "z": -4,
      "name": "Rock_Calcite_Brick_Pillar_Base",
      "rotation": 8
    },
    {
      "x": 0,
      "y": 22,
      "z": -4,
      "name": "Rock_Calcite_Brick_Ornate"
    },
    {
      "x": 0,
      "y": 24,
      "z": -4,
      "name": "Rock_Calcite_Brick_Wall"
    },
    {
      "x": 0,
      "y": 18,
      "z": -3,
      "name": "Rock_Calcite_Brick_Stairs",
      "rotation": 10
    },
    {
      "x": 0,
      "y": 21,
      "z": -1,
      "name": "Rock_Crystal_Wind_Small",
      "rotation": 6
    },
    {
      "x": 0,
      "y": 22,
      "z": -1,
      "name": "Rock_Crystal_Wind_Large",
      "rotation": 6
    },
    {
      "x": 0,
      "y": 23,
      "z": -1,
      "name": "Rock_Crystal_Wind_Small",
      "rotation": 6
    },
    {
      "x": 0,
      "y": 20,
      "z": 0,
      "name": "Rock_Crystal_Wind_Large",
      "rotation": 8
    },
    {
      "x": 0,
      "y": 21,
      "z": 0,
      "name": "Rock_Crystal_Wind_Block"
    },
    {
      "x": 0,
      "y": 22,
      "z": 0,
      "name": "Rock_Crystal_Wind_Block"
    },
    {
      "x": 0,
      "y": 23,
      "z": 0,
      "name": "Rock_Crystal_Wind_Block"
    },
    {
      "x": 0,
      "y": 24,
      "z": 0,
      "name": "Rock_Crystal_Wind_Large"
    },
    {
      "x": 0,
      "y": 21,
      "z": 1,
      "name": "Rock_Crystal_Wind_Small",
      "rotation": 4
    },
    {
      "x": 0,
      "y": 22,
      "z": 1,
      "name": "Rock_Crystal_Wind_Large",
      "rotation": 4
    },
    {
      "x": 0,
      "y": 23,
      "z": 1,
      "name": "Rock_Crystal_Wind_Small",
      "rotation": 4
    },
    {
      "x": 0,
      "y": 18,
      "z": 3,
      "name": "Rock_Calcite_Brick_Stairs",
      "rotation": 8
    },
    {
      "x": 0,
      "y": -5,
      "z": 4,
      "name": "Rock_Calcite_Brick_Smooth"
    },
    {
      "x": 0,
      "y": -4,
      "z": 4,
      "name": "Rock_Calcite_Brick_Smooth"
    },
    {
      "x": 0,
      "y": -3,
      "z": 4,
      "name": "Rock_Calcite_Brick_Smooth"
    },
    {
      "x": 0,
      "y": -2,
      "z": 4,
      "name": "Rock_Calcite_Brick_Smooth"
    },
    {
      "x": 0,
      "y": -1,
      "z": 4,
      "name": "Rock_Calcite_Brick_Smooth"
    },
    {
      "x": 0,
      "y": 0,
      "z": 4,
      "name": "Rock_Calcite_Brick_Smooth"
    },
    {
      "x": 0,
      "y": 1,
      "z": 4,
      "name": "Rock_Calcite_Brick_Pillar_Base"
    },
    {
      "x": 0,
      "y": 2,
      "z": 4,
      "name": "Rock_Calcite_Brick_Pillar_Middle",
      "rotation": 8
    },
    {
      "x": 0,
      "y": 3,
      "z": 4,
      "name": "Rock_Calcite_Brick_Pillar_Middle",
      "rotation": 8
    },
    {
      "x": 0,
      "y": 4,
      "z": 4,
      "name": "Rock_Calcite_Brick_Pillar_Middle",
      "rotation": 8
    },
    {
      "x": 0,
      "y": 5,
      "z": 4,
      "name": "Rock_Calcite_Brick_Pillar_Middle",
      "rotation": 8
    },
    {
      "x": 0,
      "y": 6,
      "z": 4,
      "name": "Rock_Calcite_Brick_Pillar_Middle",
      "rotation": 8
    },
    {
      "x": 0,
      "y": 7,
      "z": 4,
      "name": "Rock_Calcite_Brick_Pillar_Middle",
      "rotation": 8
    },
    {
      "x": 0,
      "y": 8,
      "z": 4,
      "name": "Rock_Calcite_Brick_Pillar_Base",
      "rotation": 8
    },
    {
      "x": 0,
      "y": 9,
      "z": 4,
      "name": "Rock_Crystal_Wind_Large"
    },
    {
      "x": 0,
      "y": 10,
      "z": 4,
      "name": "Rock_Calcite_Brick_Pillar_Base"
    },
    {
      "x": 0,
      "y": 11,
      "z": 4,
      "name": "Rock_Calcite_Brick_Pillar_Middle",
      "rotation": 8
    },
    {
      "x": 0,
      "y": 12,
      "z": 4,
      "name": "Rock_Calcite_Brick_Pillar_Middle",
      "rotation": 8
    },
    {
      "x": 0,
      "y": 13,
      "z": 4,
      "name": "Rock_Calcite_Brick_Pillar_Middle",
      "rotation": 8
    },
    {
      "x": 0,
      "y": 14,
      "z": 4,
      "name": "Rock_Calcite_Brick_Pillar_Middle",
      "rotation": 8
    },
    {
      "x": 0,
      "y": 15,
      "z": 4,
      "name": "Rock_Calcite_Brick_Pillar_Middle"
    },
    {
      "x": 0,
      "y": 16,
      "z": 4,
      "name": "Rock_Calcite_Brick_Pillar_Middle"
    },
    {
      "x": 0,
      "y": 17,
      "z": 4,
      "name": "Rock_Calcite_Brick_Pillar_Base",
      "rotation": 8
    },
    {
      "x": 0,
      "y": 18,
      "z": 4,
      "name": "Rock_Calcite_Brick_Smooth"
    },
    {
      "x": 0,
      "y": 19,
      "z": 4,
      "name": "Rock_Crystal_Wind_Large",
      "rotation": 8
    },
    {
      "x": 0,
      "y": 20,
      "z": 4,
      "name": "Rock_Calcite_Brick_Pillar_Base"
    },
    {
      "x": 0,
      "y": 21,
      "z": 4,
      "name": "Rock_Calcite_Brick_Pillar_Base",
      "rotation": 8
    },
    {
      "x": 0,
      "y": 22,
      "z": 4,
      "name": "Rock_Calcite_Brick_Ornate"
    },
    {
      "x": 0,
      "y": 24,
      "z": 4,
      "name": "Rock_Calcite_Brick_Wall"
    },
    {
      "x": 0,
      "y": 18,
      "z": 5,
      "name": "Rock_Calcite_Brick_Stairs",
      "rotation": 10
    },
    {
      "x": 1,
      "y": 18,
      "z": -5,
      "name": "*Rock_Calcite_Brick_Stairs_State_Definitions_Corner_Right",
      "rotation": 11
    },
    {
      "x": 1,
      "y": 18,
      "z": -4,
      "name": "*Rock_Calcite_Brick_Stairs_State_Definitions_Corner_Left",
      "rotation": 8
    },
    {
      "x": 1,
      "y": 22,
      "z": -4,
      "name": "Rock_Calcite_Brick_Half",
      "rotation": 5
    },
    {
      "x": 1,
      "y": 23,
      "z": -4,
      "name": "Rock_Calcite_Brick_Roof_Steep",
      "rotation": 3
    },
    {
      "x": 1,
      "y": 24,
      "z": -4,
      "name": "Rock_Calcite_Brick_Roof_Steep",
      "filler": 1024,
      "rotation": 3
    },
    {
      "x": 1,
      "y": 18,
      "z": -3,
      "name": "*Rock_Calcite_Brick_Stairs_State_Definitions_Corner_Left",
      "rotation": 11
    },
    {
      "x": 1,
      "y": 21,
      "z": 0,
      "name": "Rock_Crystal_Wind_Small",
      "rotation": 5
    },
    {
      "x": 1,
      "y": 22,
      "z": 0,
      "name": "Rock_Crystal_Wind_Large",
      "rotation": 5
    },
    {
      "x": 1,
      "y": 23,
      "z": 0,
      "name": "Rock_Crystal_Wind_Small",
      "rotation": 5
    },
    {
      "x": 1,
      "y": 18,
      "z": 3,
      "name": "*Rock_Calcite_Brick_Stairs_State_Definitions_Corner_Left",
      "rotation": 8
    },
    {
      "x": 1,
      "y": 18,
      "z": 4,
      "name": "Rock_Calcite_Brick_Stairs",
      "rotation": 11
    },
    {
      "x": 1,
      "y": 22,
      "z": 4,
      "name": "Rock_Calcite_Brick_Half",
      "rotation": 5
    },
    {
      "x": 1,
      "y": 23,
      "z": 4,
      "name": "Rock_Calcite_Brick_Roof_Steep",
      "rotation": 3
    },
    {
      "x": 1,
      "y": 24,
      "z": 4,
      "name": "Rock_Calcite_Brick_Roof_Steep",
      "filler": 1024,
      "rotation": 3
    },
    {
      "x": 1,
      "y": 18,
      "z": 5,
      "name": "*Rock_Calcite_Brick_Stairs_State_Definitions_Corner_Left",
      "rotation": 11
    },
    {
      "x": 2,
      "y": 25,
      "z": -4,
      "name": "Rock_Calcite_Brick_Roof_Hollow",
      "rotation": 3
    },
    {
      "x": 2,
      "y": 25,
      "z": 4,
      "name": "Rock_Calcite_Brick_Roof_Hollow",
      "rotation": 3
    },
    {
      "x": 3,
      "y": 26,
      "z": -4,
      "name": "Rock_Calcite_Brick_Roof_Hollow",
      "rotation": 3
    },
    {
      "x": 3,
      "y": 18,
      "z": -1,
      "name": "*Rock_Calcite_Brick_Stairs_State_Definitions_Corner_Left",
      "rotation": 9
    },
    {
      "x": 3,
      "y": 18,
      "z": 0,
      "name": "Rock_Calcite_Brick_Stairs",
      "rotation": 9
    },
    {
      "x": 3,
      "y": 18,
      "z": 1,
      "name": "*Rock_Calcite_Brick_Stairs_State_Definitions_Corner_Left",
      "rotation": 10
    },
    {
      "x": 3,
      "y": 26,
      "z": 4,
      "name": "Rock_Calcite_Brick_Roof_Hollow",
      "rotation": 3
    },
    {
      "x": 4,
      "y": 26,
      "z": -3,
      "name": "Rock_Calcite_Brick_Roof_Hollow"
    },
    {
      "x": 4,
      "y": 25,
      "z": -2,
      "name": "Rock_Calcite_Brick_Roof_Hollow"
    },
    {
      "x": 4,
      "y": 18,
      "z": -1,
      "name": "Rock_Calcite_Brick_Stairs",
      "rotation": 8
    },
    {
      "x": 4,
      "y": 22,
      "z": -1,
      "name": "Rock_Calcite_Brick_Half",
      "rotation": 6
    },
    {
      "x": 4,
      "y": 23,
      "z": -1,
      "name": "Rock_Calcite_Brick_Roof_Steep"
    },
    {
      "x": 4,
      "y": 24,
      "z": -1,
      "name": "Rock_Calcite_Brick_Roof_Steep",
      "filler": 1024
    },
    {
      "x": 4,
      "y": -5,
      "z": 0,
      "name": "Rock_Calcite_Brick_Smooth"
    },
    {
      "x": 4,
      "y": -4,
      "z": 0,
      "name": "Rock_Calcite_Brick_Smooth"
    },
    {
      "x": 4,
      "y": -3,
      "z": 0,
      "name": "Rock_Calcite_Brick_Smooth"
    },
    {
      "x": 4,
      "y": -2,
      "z": 0,
      "name": "Rock_Calcite_Brick_Smooth"
    },
    {
      "x": 4,
      "y": -1,
      "z": 0,
      "name": "Rock_Calcite_Brick_Smooth"
    },
    {
      "x": 4,
      "y": 0,
      "z": 0,
      "name": "Rock_Calcite_Brick_Smooth"
    },
    {
      "x": 4,
      "y": 1,
      "z": 0,
      "name": "Rock_Calcite_Brick_Pillar_Base"
    },
    {
      "x": 4,
      "y": 2,
      "z": 0,
      "name": "Rock_Calcite_Brick_Pillar_Middle",
      "rotation": 8
    },
    {
      "x": 4,
      "y": 3,
      "z": 0,
      "name": "Rock_Calcite_Brick_Pillar_Middle",
      "rotation": 8
    },
    {
      "x": 4,
      "y": 4,
      "z": 0,
      "name": "Rock_Calcite_Brick_Pillar_Middle",
      "rotation": 8
    },
    {
      "x": 4,
      "y": 5,
      "z": 0,
      "name": "Rock_Calcite_Brick_Pillar_Middle",
      "rotation": 8
    },
    {
      "x": 4,
      "y": 6,
      "z": 0,
      "name": "Rock_Calcite_Brick_Pillar_Middle",
      "rotation": 8
    },
    {
      "x": 4,
      "y": 7,
      "z": 0,
      "name": "Rock_Calcite_Brick_Pillar_Middle",
      "rotation": 8
    },
    {
      "x": 4,
      "y": 8,
      "z": 0,
      "name": "Rock_Calcite_Brick_Pillar_Base",
      "rotation": 8
    },
    {
      "x": 4,
      "y": 9,
      "z": 0,
      "name": "Rock_Crystal_Wind_Large"
    },
    {
      "x": 4,
      "y": 10,
      "z": 0,
      "name": "Rock_Calcite_Brick_Pillar_Base"
    },
    {
      "x": 4,
      "y": 11,
      "z": 0,
      "name": "Rock_Calcite_Brick_Pillar_Middle",
      "rotation": 8
    },
    {
      "x": 4,
      "y": 12,
      "z": 0,
      "name": "Rock_Calcite_Brick_Pillar_Middle",
      "rotation": 8
    },
    {
      "x": 4,
      "y": 13,
      "z": 0,
      "name": "Rock_Calcite_Brick_Pillar_Middle",
      "rotation": 8
    },
    {
      "x": 4,
      "y": 14,
      "z": 0,
      "name": "Rock_Calcite_Brick_Pillar_Middle",
      "rotation": 8
    },
    {
      "x": 4,
      "y": 15,
      "z": 0,
      "name": "Rock_Calcite_Brick_Pillar_Middle"
    },
    {
      "x": 4,
      "y": 16,
      "z": 0,
      "name": "Rock_Calcite_Brick_Pillar_Middle"
    },
    {
      "x": 4,
      "y": 17,
      "z": 0,
      "name": "Rock_Calcite_Brick_Pillar_Base",
      "rotation": 8
    },
    {
      "x": 4,
      "y": 18,
      "z": 0,
      "name": "Rock_Calcite_Brick_Smooth"
    },
    {
      "x": 4,
      "y": 19,
      "z": 0,
      "name": "Rock_Crystal_Wind_Large",
      "rotation": 11
    },
    {
      "x": 4,
      "y": 20,
      "z": 0,
      "name": "Rock_Calcite_Brick_Pillar_Base",
      "rotation": 3
    },
    {
      "x": 4,
      "y": 21,
      "z": 0,
      "name": "Rock_Calcite_Brick_Pillar_Base",
      "rotation": 11
    },
    {
      "x": 4,
      "y": 22,
      "z": 0,
      "name": "Rock_Calcite_Brick_Ornate",
      "rotation": 3
    },
    {
      "x": 4,
      "y": 24,
      "z": 0,
      "name": "Rock_Calcite_Brick_Wall",
      "rotation": 3
    },
    {
      "x": 4,
      "y": 18,
      "z": 1,
      "name": "Rock_Calcite_Brick_Stairs",
      "rotation": 10
    },
    {
      "x": 4,
      "y": 22,
      "z": 1,
      "name": "Rock_Calcite_Brick_Half",
      "rotation": 4
    },
    {
      "x": 4,
      "y": 23,
      "z": 1,
      "name": "Rock_Calcite_Brick_Roof_Steep",
      "rotation": 2
    },
    {
      "x": 4,
      "y": 24,
      "z": 1,
      "name": "Rock_Calcite_Brick_Roof_Steep",
      "filler": 1024,
      "rotation": 2
    },
    {
      "x": 4,
      "y": 25,
      "z": 2,
      "name": "Rock_Calcite_Brick_Roof_Hollow",
      "rotation": 2
    },
    {
      "x": 4,
      "y": 26,
      "z": 3,
      "name": "Rock_Calcite_Brick_Roof_Hollow",
      "rotation": 2
    },
    {
      "x": 5,
      "y": 18,
      "z": -1,
      "name": "*Rock_Calcite_Brick_Stairs_State_Definitions_Corner_Left",
      "rotation": 8
    },
    {
      "x": 5,
      "y": 18,
      "z": 0,
      "name": "Rock_Calcite_Brick_Stairs",
      "rotation": 11
    },
    {
      "x": 5,
      "y": 18,
      "z": 1,
      "name": "*Rock_Calcite_Brick_Stairs_State_Definitions_Corner_Left",
      "rotation": 11
    }
  ]
}